[2022-11-19T12:42:47.962+0000] {taskinstance.py:1165} INFO - Dependencies all met for <TaskInstance: Call_Center_ETL_DAG.load_data_to_staging_call_table manual__2022-11-19T12:42:28.293009+00:00 [queued]>
[2022-11-19T12:42:47.992+0000] {taskinstance.py:1165} INFO - Dependencies all met for <TaskInstance: Call_Center_ETL_DAG.load_data_to_staging_call_table manual__2022-11-19T12:42:28.293009+00:00 [queued]>
[2022-11-19T12:42:47.994+0000] {taskinstance.py:1362} INFO - 
--------------------------------------------------------------------------------
[2022-11-19T12:42:47.996+0000] {taskinstance.py:1363} INFO - Starting attempt 1 of 1
[2022-11-19T12:42:47.997+0000] {taskinstance.py:1364} INFO - 
--------------------------------------------------------------------------------
[2022-11-19T12:42:48.062+0000] {taskinstance.py:1383} INFO - Executing <Task(MySqlOperator): load_data_to_staging_call_table> on 2022-11-19 12:42:28.293009+00:00
[2022-11-19T12:42:48.076+0000] {standard_task_runner.py:55} INFO - Started process 1177 to run task
[2022-11-19T12:42:48.089+0000] {standard_task_runner.py:82} INFO - Running: ['***', 'tasks', 'run', 'Call_Center_ETL_DAG', 'load_data_to_staging_call_table', 'manual__2022-11-19T12:42:28.293009+00:00', '--job-id', '101', '--raw', '--subdir', 'DAGS_FOLDER/create_database_tables.py', '--cfg-path', '/tmp/tmpjeq8jj04']
[2022-11-19T12:42:48.091+0000] {standard_task_runner.py:83} INFO - Job 101: Subtask load_data_to_staging_call_table
[2022-11-19T12:42:48.630+0000] {task_command.py:376} INFO - Running <TaskInstance: Call_Center_ETL_DAG.load_data_to_staging_call_table manual__2022-11-19T12:42:28.293009+00:00 [running]> on host 6e77c1f44c06
[2022-11-19T12:42:49.281+0000] {taskinstance.py:1592} INFO - Exporting the following env vars:
AIRFLOW_CTX_DAG_OWNER=Abdelrhman Yassein
AIRFLOW_CTX_DAG_ID=Call_Center_ETL_DAG
AIRFLOW_CTX_TASK_ID=load_data_to_staging_call_table
AIRFLOW_CTX_EXECUTION_DATE=2022-11-19T12:42:28.293009+00:00
AIRFLOW_CTX_TRY_NUMBER=1
AIRFLOW_CTX_DAG_RUN_ID=manual__2022-11-19T12:42:28.293009+00:00
[2022-11-19T12:42:49.285+0000] {mysql.py:84} INFO - Executing: 
    SET GLOBAL local_infile=1;
            LOAD DATA LOCAL INFILE 'G:/docker-files/CallCenter.csv'
            INTO TABLE staging_call
            COLUMNS TERMINATED BY ','
            OPTIONALLY ENCLOSED BY '"'
            ESCAPED BY '"'
            LINES TERMINATED BY '
'
            IGNORE 1 LINES;
            
[2022-11-19T12:42:49.353+0000] {base.py:71} INFO - Using connection ID 'mysql_conn_id' for task execution.
[2022-11-19T12:42:49.517+0000] {sql.py:315} INFO - Running statement: 
    SET GLOBAL local_infile=1;
            LOAD DATA LOCAL INFILE 'G:/docker-files/CallCenter.csv'
            INTO TABLE staging_call
            COLUMNS TERMINATED BY ','
            OPTIONALLY ENCLOSED BY '"'
            ESCAPED BY '"'
            LINES TERMINATED BY '
'
            IGNORE 1 LINES;
            , parameters: None
[2022-11-19T12:42:49.526+0000] {sql.py:324} INFO - Rows affected: 0
[2022-11-19T12:42:49.535+0000] {taskinstance.py:1851} ERROR - Task failed with exception
Traceback (most recent call last):
  File "/home/airflow/.local/lib/python3.7/site-packages/airflow/providers/mysql/operators/mysql.py", line 86, in execute
    hook.run(self.sql, autocommit=self.autocommit, parameters=self.parameters)
  File "/home/airflow/.local/lib/python3.7/site-packages/airflow/providers/common/sql/hooks/sql.py", line 299, in run
    results.append(result)
  File "/usr/local/lib/python3.7/contextlib.py", line 298, in __exit__
    self.thing.close()
  File "/home/airflow/.local/lib/python3.7/site-packages/MySQLdb/cursors.py", line 83, in close
    while self.nextset():
  File "/home/airflow/.local/lib/python3.7/site-packages/MySQLdb/cursors.py", line 137, in nextset
    nr = db.next_result()
MySQLdb.InternalError: (2, "File 'G:/docker-files/CallCenter.csv' not found (OS errno 2 - No such file or directory)")
[2022-11-19T12:42:49.585+0000] {taskinstance.py:1406} INFO - Marking task as FAILED. dag_id=Call_Center_ETL_DAG, task_id=load_data_to_staging_call_table, execution_date=20221119T124228, start_date=20221119T124247, end_date=20221119T124249
[2022-11-19T12:42:49.689+0000] {standard_task_runner.py:105} ERROR - Failed to execute job 101 for task load_data_to_staging_call_table ((2, "File 'G:/docker-files/CallCenter.csv' not found (OS errno 2 - No such file or directory)"); 1177)
[2022-11-19T12:42:49.747+0000] {local_task_job.py:159} INFO - Task exited with return code 1
[2022-11-19T12:42:49.817+0000] {taskinstance.py:2623} INFO - 0 downstream tasks scheduled from follow-on schedule check
