[2022-11-20T13:11:46.477+0000] {taskinstance.py:1165} INFO - Dependencies all met for <TaskInstance: Call_Center_ETL_DAG.insert_fact_call_data scheduled__2022-11-18T00:00:00+00:00 [queued]>
[2022-11-20T13:11:46.883+0000] {taskinstance.py:1165} INFO - Dependencies all met for <TaskInstance: Call_Center_ETL_DAG.insert_fact_call_data scheduled__2022-11-18T00:00:00+00:00 [queued]>
[2022-11-20T13:11:46.889+0000] {taskinstance.py:1362} INFO - 
--------------------------------------------------------------------------------
[2022-11-20T13:11:46.891+0000] {taskinstance.py:1363} INFO - Starting attempt 1 of 1
[2022-11-20T13:11:46.892+0000] {taskinstance.py:1364} INFO - 
--------------------------------------------------------------------------------
[2022-11-20T13:11:47.054+0000] {taskinstance.py:1383} INFO - Executing <Task(MySqlOperator): insert_fact_call_data> on 2022-11-18 00:00:00+00:00
[2022-11-20T13:11:47.102+0000] {standard_task_runner.py:55} INFO - Started process 736 to run task
[2022-11-20T13:11:47.178+0000] {standard_task_runner.py:82} INFO - Running: ['***', 'tasks', 'run', 'Call_Center_ETL_DAG', 'insert_fact_call_data', 'scheduled__2022-11-18T00:00:00+00:00', '--job-id', '156', '--raw', '--subdir', 'DAGS_FOLDER/call_center_dag.py', '--cfg-path', '/tmp/tmpr4_cou_p']
[2022-11-20T13:11:47.184+0000] {standard_task_runner.py:83} INFO - Job 156: Subtask insert_fact_call_data
[2022-11-20T13:11:47.997+0000] {task_command.py:376} INFO - Running <TaskInstance: Call_Center_ETL_DAG.insert_fact_call_data scheduled__2022-11-18T00:00:00+00:00 [running]> on host 9eba6bc17a61
[2022-11-20T13:11:49.724+0000] {taskinstance.py:1592} INFO - Exporting the following env vars:
AIRFLOW_CTX_DAG_OWNER=Abdelrhman Yassein
AIRFLOW_CTX_DAG_ID=Call_Center_ETL_DAG
AIRFLOW_CTX_TASK_ID=insert_fact_call_data
AIRFLOW_CTX_EXECUTION_DATE=2022-11-18T00:00:00+00:00
AIRFLOW_CTX_TRY_NUMBER=1
AIRFLOW_CTX_DAG_RUN_ID=scheduled__2022-11-18T00:00:00+00:00
[2022-11-20T13:11:49.740+0000] {mysql.py:84} INFO - Executing: 
        INSERT INTO call_fact(call_id,customer_id,call_date,csat_score,call_in_minutes)
        SELECT DISTINCT
            st.id as call_id,
            c.customer_id ,
            STR_TO_DATE(call_timestamp, '%m/%d/%Y') AS call_date,
            CASE
                WHEN st.csat_score = ' ' THEN 1
                WHEN st.csat_score = 0 THEN 1
            END AS  csat_score,
            call_minutes
        FROM 
            staging_call st
        join customers c 
        on st.customer_name = c.customer_name
        WHERE
            id IS NOT NULL;
        
[2022-11-20T13:11:49.855+0000] {base.py:71} INFO - Using connection ID 'mysql_conn_id' for task execution.
[2022-11-20T13:11:50.263+0000] {sql.py:315} INFO - Running statement: 
        INSERT INTO call_fact(call_id,customer_id,call_date,csat_score,call_in_minutes)
        SELECT DISTINCT
            st.id as call_id,
            c.customer_id ,
            STR_TO_DATE(call_timestamp, '%m/%d/%Y') AS call_date,
            CASE
                WHEN st.csat_score = ' ' THEN 1
                WHEN st.csat_score = 0 THEN 1
            END AS  csat_score,
            call_minutes
        FROM 
            staging_call st
        join customers c 
        on st.customer_name = c.customer_name
        WHERE
            id IS NOT NULL;
        , parameters: None
[2022-11-20T13:11:50.320+0000] {taskinstance.py:1851} ERROR - Task failed with exception
Traceback (most recent call last):
  File "/home/airflow/.local/lib/python3.7/site-packages/airflow/providers/mysql/operators/mysql.py", line 86, in execute
    hook.run(self.sql, autocommit=self.autocommit, parameters=self.parameters)
  File "/home/airflow/.local/lib/python3.7/site-packages/airflow/providers/common/sql/hooks/sql.py", line 295, in run
    self._run_command(cur, sql_statement, parameters)
  File "/home/airflow/.local/lib/python3.7/site-packages/airflow/providers/common/sql/hooks/sql.py", line 320, in _run_command
    cur.execute(sql_statement)
  File "/home/airflow/.local/lib/python3.7/site-packages/MySQLdb/cursors.py", line 206, in execute
    res = self._query(query)
  File "/home/airflow/.local/lib/python3.7/site-packages/MySQLdb/cursors.py", line 319, in _query
    db.query(q)
  File "/home/airflow/.local/lib/python3.7/site-packages/MySQLdb/connections.py", line 254, in query
    _mysql.connection.query(self, query)
MySQLdb.ProgrammingError: (1146, "Table 'call_center.call_fact' doesn't exist")
[2022-11-20T13:11:50.649+0000] {taskinstance.py:1406} INFO - Marking task as FAILED. dag_id=Call_Center_ETL_DAG, task_id=insert_fact_call_data, execution_date=20221118T000000, start_date=20221120T131146, end_date=20221120T131150
[2022-11-20T13:11:51.056+0000] {standard_task_runner.py:105} ERROR - Failed to execute job 156 for task insert_fact_call_data ((1146, "Table 'call_center.call_fact' doesn't exist"); 736)
[2022-11-20T13:11:51.193+0000] {local_task_job.py:159} INFO - Task exited with return code 1
[2022-11-20T13:11:51.467+0000] {taskinstance.py:2623} INFO - 0 downstream tasks scheduled from follow-on schedule check
